Workbook

Sheet Class Results
A1: RMA2v2 | V1: =X1 -> RMA2v2 | X1: RMA2v2
A2: School Rapid Mathematics Assessment Results
A4: SCHOOL ID : | B4: 107460 | E4: Medium of Instruction (MOI)
A5: SCHOOL NAME: | B5: PANAY ELEMENTARY SCHOOL | E5: Grade 1 | G5: Grade 2 | I5: Grade 3
E6: Tagalog | G6: Tagalog | I6: Tagalog
A8: Grade | D8: Language Matched ( LOI vs Learners) | E8: Number of Learners Assessed | F8: Total Enrolment | G8: Number of Learners Assessed | L8: Number of Learners with Correct Answers >=75 | X8: Status
B9: Section | C9: Sex | G9: Emerging (Not Proficient) | H9: Emerging (Low Proficient) | I9: Developing (Nearly Proficient) | J9: Transitioning (Proficient) | K9: At Grade Level (Highly Proficient) | L9: Task A | M9: Task B | N9: Task C | O9: Task D | P9: Task E | Q9: Task F | R9: Task G | S9: Task H | T9: Task I | U9: Task J | V9: Task K | W9: Average Overall Score
X10: =IF(ISBLANK(A10)," ",IF(SUM(G10:K10)=E10,"Data Validated","Data with Error")) -> Data Validated | AA10: Language
X11: =IF(ISBLANK(A11)," ",IF(SUM(G11:K11)=E11,"Data Validated","Data with Error")) -> Data Validated | AA11: Akeanon
AA12: Bahasa Sug
AA13: Bikol Libon
AA14: Buhi-non
AA15: Central Bikol
AA16: Chavacano
AA17: Caluyanen
AA18: Cuyonon
AA19: English
AA20: Hiligaynon
AA21: Ibanag
AA22: Ilocano
AA23: Inabaknon
... AA38: Northern Sorsoganon
W39: {=IF(A39<>"",_xlfn.IFS(A39="Grade 1",SUM(L39:S39),A39="Grade 2",SUM(L39:V39),A39="Grade 3",SUM(L39:S39)),"")} | AA39: Southern Sorsoganon
W40: {=IF(A40<>"",_xlfn.IFS(A40="Grade 1",SUM(L40:S40),A40="Grade 2",SUM(L40:V40),A40="Grade 3",SUM(L40:S40)),"")} | AA40: Surigaonon
W41: {=IF(A41<>"",_xlfn.IFS(A41="Grade 1",SUM(L41:S41),A41="Grade 2",SUM(L41:V41),A41="Grade 3",SUM(L41:S41)),"")} | AA41: Tagalog
W42: {=IF(A42<>"",_xlfn.IFS(A42="Grade 1",SUM(L42:S42),A42="Grade 2",SUM(L42:V42),A42="Grade 3",SUM(L42:S42)),"")} | AA42: Waray
W43: {=IF(A43<>"",_xlfn.IFS(A43="Grade 1",SUM(L43:S43),A43="Grade 2",SUM(L43:V43),A43="Grade 3",SUM(L43:S43)),"")} | AA43: West Albay Bikol
W44: {=IF(A44<>"",_xlfn.IFS(A44="Grade 1",SUM(L44:S44),A44="Grade 2",SUM(L44:V44),A44="Grade 3",SUM(L44:S44)),"")} | AA44: Yakan
W45: {=IF(A45<>"",_xlfn.IFS(A45="Grade 1",SUM(L45:S45),A45="Grade 2",SUM(L45:V45),A45="Grade 3",SUM(L45:S45)),"")} | AA45: Other MT
W46: {=IF(A46<>"",_xlfn.IFS(A46="Grade 1",SUM(L46:S46),A46="Grade 2",SUM(L46:V46),A46="Grade 3",SUM(L46:S46)),"")}
W47: {=IF(A47<>"",_xlfn.IFS(A47="Grade 1",SUM(L47:S47),A47="Grade 2",SUM(L47:V47),A47="Grade 3",SUM(L47:S47)),"")}
W48: {=IF(A48<>"",_xlfn.IFS(A48="Grade 1",SUM(L48:S48),A48="Grade 2",SUM(L48:V48),A48="Grade 3",SUM(L48:S48)),"")}
W49: {=IF(A49<>"",_xlfn.IFS(A49="Grade 1",SUM(L49:S49),A49="Grade 2",SUM(L49:V49),A49="Grade 3",SUM(L49:S49)),"")}
W50: {=IF(A50<>"",_xlfn.IFS(A50="Grade 1",SUM(L50:S50),A50="Grade 2",SUM(L50:V50),A50="Grade 3",SUM(L50:S50)),"")}
W51: {=IF(A51<>"",_xlfn.IFS(A51="Grade 1",SUM(L51:S51),A51="Grade 2",SUM(L51:V51),A51="Grade 3",SUM(L51:S51)),"")}
W52: {=IF(A52<>"",_xlfn.IFS(A52="Grade 1",SUM(L52:S52),A52="Grade 2",SUM(L52:V52),A52="Grade 3",SUM(L52:S52)),"")}
W53: {=IF(A53<>"",_xlfn.IFS(A53="Grade 1",SUM(L53:S53),A53="Grade 2",SUM(L53:V53),A53="Grade 3",SUM(L53:S53)),"")}
W54: {=IF(A54<>"",_xlfn.IFS(A54="Grade 1",SUM(L54:S54),A54="Grade 2",SUM(L54:V54),A54="Grade 3",SUM(L54:S54)),"")}
W55: {=IF(A55<>"",_xlfn.IFS(A55="Grade 1",SUM(L55:S55),A55="Grade 2",SUM(L55:V55),A55="Grade 3",SUM(L55:S55)),"")}
W56: {=IF(A56<>"",_xlfn.IFS(A56="Grade 1",SUM(L56:S56),A56="Grade 2",SUM(L56:V56),A56="Grade 3",SUM(L56:S56)),"")}
...

Sheet School Summary
A1: RMA2v2 | X1: ='Class Results'!$X$1 -> RMA2v2
A2: School Rapid Mathematics Assessment Summary
I3: Male | J3: =D11+D13+D15 -> 11
I4: Female | J4: =D12+D14+D16 -> 13
A5: SCHOOL ID : | B5: ='Class Results'!B4 -> 107460 | G5: Medium of Instruction (MOI)
A6: SCHOOL NAME | B6: ='Class Results'!$B$5 -> PANAY ELEMENTARY SCHOOL | G6: Grade 1 | I6: Grade 2 | K6: Grade 3 | BC6: Total Score
G7: ='Class Results'!E6 -> Tagalog | I7: ='Class Results'!G6 -> Tagalog | K7: ='Class Results'!I6 -> Tagalog | BC7: Grade 1 | BD7: 35
BC8: Grade 2 | BD8: 25
C9: Language Matched ( LOI vs Learners) | D9: Number of Learners Assessed | E9: Total Enrolment | F9: Number of Learners Assessed | L9: Number of Learners Who Passed 75% Per Task by Grade Level | W9: Average Overall Score | AD9: Total Items | BC9: Grade 3 | BD9: 20
A10: Grade | B10: Sex | F10: Emerging (Not Proficient) | G10: Emerging (Low Proficient) | H10: Developing (Nearly Proficient) | I10: Transitioning (Proficient) | J10: At Grade Level (Highly Proficient) | L10: Task A | M10: Task B | N10: Task C | O10: Task D | P10: Task E | Q10: Task F | R10: Task G | S10: Task H | T10: Task I | U10: Task J | V10: Task K | AD10: Task A | AE10: Task B | AF10: Task C | AG10: Task D | AH10: Task E | AI10: Task F | AJ10: Task G | AK10: Task H | AL10: Task I | AM10: Task J | AN10: Task K | AO10: Total
A11: Grade 1 | B11: Male | C11: =SUMIFS('Class Results'!D$10:D$362,'Class Results'!$A$10:$A$362,$A11, 'Class Results'!$C$10:$C$362,$B11) -> 3 | D11: =SUMIFS('Class Results'!E$10:E$362,'Class Results'!$A$10:$A$362,$A11, 'Class Results'!$C$10:$C$362,$B11) -> 3 | E11: =SUMIFS('Class Results'!F$10:F$362,'Class Results'!$A$10:$A$362,$A11, 'Class Results'!$C$10:$C$362,$B11) -> 3 | F11: =SUMIFS('Class Results'!G$10:G$362,'Class Results'!$A$10:$A$362,$A11, 'Class Results'!$C$10:$C$362,$B11) -> 0 | G11: =SUMIFS('Class Results'!H$10:H$362,'Class Results'!$A$10:$A$362,$A11, 'Class Results'!$C$10:$C$362,$B11) -> 0 | H11: =SUMIFS('Class Results'!I$10:I$362,'Class Results'!$A$10:$A$362,$A11, 'Class Results'!$C$10:$C$362,$B11) -> 2 | I11: =SUMIFS('Class Results'!J$10:J$362,'Class Results'!$A$10:$A$362,$A11, 'Class Results'!$C$10:$C$362,$B11) -> 1 | J11: =SUMIFS('Class Results'!K$10:K$362,'Class Results'!$A$10:$A$362,$A11, 'Class Results'!$C$10:$C$362,$B11) -> 0 | L11: =SUMIFS('Class Results'!L$10:L$362,'Class Results'!$A$10:$A$362,$A11, 'Class Results'!$C$10:$C$362,$B11) -> 0 | M11: =SUMIFS('Class Results'!M$10:M$362,'Class Results'!$A$10:$A$362,$A11, 'Class Results'!$C$10:$C$362,$B11) -> 1 | N11: =SUMIFS('Class Results'!N$10:N$362,'Class Results'!$A$10:$A$362,$A11, 'Class Results'!$C$10:$C$362,$B11) -> 2 | O11: =SUMIFS('Class Results'!O$10:O$362,'Class Results'!$A$10:$A$362,$A11, 'Class Results'!$C$10:$C$362,$B11) -> 0 | P11: =SUMIFS('Class Results'!P$10:P$362,'Class Results'!$A$10:$A$362,$A11, 'Class Results'!$C$10:$C$362,$B11) -> 1 | Q11: =SUMIFS('Class Results'!Q$10:Q$362,'Class Results'!$A$10:$A$362,$A11, 'Class Results'!$C$10:$C$362,$B11) -> 3 | R11: =SUMIFS('Class Results'!R$10:R$362,'Class Results'!$A$10:$A$362,$A11, 'Class Results'!$C$10:$C$362,$B11) -> 1 | S11: =SUMIFS('Class Results'!S$10:S$362,'Class Results'!$A$10:$A$362,$A11, 'Class Results'!$C$10:$C$362,$B11) -> 2 | W11: =IFERROR(AVERAGEIFS('Class Results'!W$10:W$362,'Class Results'!$A$10:$A$362,$A11, 'Class Results'!$C$10:$C$362,$B11),"") -> 25.33 | AD11: 8 | AE11: 2 | AF11: 8 | AG11: 6 | AH11: 4 | AI11: 1 | AJ11: 3 | AK11: 3 | AO11: =SUM(AD11:AL11) -> 35
A12: Grade 1 | B12: Female | C12: =SUMIFS('Class Results'!D$10:D$362,'Class Results'!$A$10:$A$362,$A12, 'Class Results'!$C$10:$C$362,$B12) -> 3 | D12: =SUMIFS('Class Results'!E$10:E$362,'Class Results'!$A$10:$A$362,$A12, 'Class Results'!$C$10:$C$362,$B12) -> 4 | E12: =SUMIFS('Class Results'!F$10:F$362,'Class Results'!$A$10:$A$362,$A12, 'Class Results'!$C$10:$C$362,$B12) -> 4 | F12: =SUMIFS('Class Results'!G$10:G$362,'Class Results'!$A$10:$A$362,$A12, 'Class Results'!$C$10:$C$362,$B12) -> 0 | G12: =SUMIFS('Class Results'!H$10:H$362,'Class Results'!$A$10:$A$362,$A12, 'Class Results'!$C$10:$C$362,$B12) -> 3 | H12: =SUMIFS('Class Results'!I$10:I$362,'Class Results'!$A$10:$A$362,$A12, 'Class Results'!$C$10:$C$362,$B12) -> 1 | I12: =SUMIFS('Class Results'!J$10:J$362,'Class Results'!$A$10:$A$362,$A12, 'Class Results'!$C$10:$C$362,$B12) -> 0 | J12: =SUMIFS('Class Results'!K$10:K$362,'Class Results'!$A$10:$A$362,$A12, 'Class Results'!$C$10:$C$362,$B12) -> 0 | L12: =SUMIFS('Class Results'!L$10:L$362,'Class Results'!$A$10:$A$362,$A12, 'Class Results'!$C$10:$C$362,$B12) -> 0 | M12: =SUMIFS('Class Results'!M$10:M$362,'Class Results'!$A$10:$A$362,$A12, 'Class Results'!$C$10:$C$362,$B12) -> 2 | N12: =SUMIFS('Class Results'!N$10:N$362,'Class Results'!$A$10:$A$362,$A12, 'Class Results'!$C$10:$C$362,$B12) -> 1 | O12: =SUMIFS('Class Results'!O$10:O$362,'Class Results'!$A$10:$A$362,$A12, 'Class Results'!$C$10:$C$362,$B12) -> 0 | P12: =SUMIFS('Class Results'!P$10:P$362,'Class Results'!$A$10:$A$362,$A12, 'Class Results'!$C$10:$C$362,$B12) -> 0 | Q12: =SUMIFS('Class Results'!Q$10:Q$362,'Class Results'!$A$10:$A$362,$A12, 'Class Results'!$C$10:$C$362,$B12) -> 2 | R12: =SUMIFS('Class Results'!R$10:R$362,'Class Results'!$A$10:$A$362,$A12, 'Class Results'!$C$10:$C$362,$B12) -> 2 | S12: =SUMIFS('Class Results'!S$10:S$362,'Class Results'!$A$10:$A$362,$A12, 'Class Results'!$C$10:$C$362,$B12) -> 2 | W12: =IFERROR(AVERAGEIFS('Class Results'!W$10:W$362,'Class Results'!$A$10:$A$362,$A12, 'Class Results'!$C$10:$C$362,$B12),"") -> 15.25 | AD12: 3 | AE12: 1 | AF12: 2 | AG12: 1 | AH12: 4 | AI12: 3 | AJ12: 3 | AK12: 4 | AL12: 2 | AM12: 1 | AN12: 1 | AO12: =SUM(AD12:AN12) -> 25
A13: Grade 2 | B13: =B11 -> Male | C13: =SUMIFS('Class Results'!D$10:D$362,'Class Results'!$A$10:$A$362,$A13, 'Class Results'!$C$10:$C$362,$B13) -> 4 | D13: =SUMIFS('Class Results'!E$10:E$362,'Class Results'!$A$10:$A$362,$A13, 'Class Results'!$C$10:$C$362,$B13) -> 4 | E13: =SUMIFS('Class Results'!F$10:F$362,'Class Results'!$A$10:$A$362,$A13, 'Class Results'!$C$10:$C$362,$B13) -> 4 | F13: =SUMIFS('Class Results'!G$10:G$362,'Class Results'!$A$10:$A$362,$A13, 'Class Results'!$C$10:$C$362,$B13) -> 2 | G13: =SUMIFS('Class Results'!H$10:H$362,'Class Results'!$A$10:$A$362,$A13, 'Class Results'!$C$10:$C$362,$B13) -> 1 | H13: =SUMIFS('Class Results'!I$10:I$362,'Class Results'!$A$10:$A$362,$A13, 'Class Results'!$C$10:$C$362,$B13) -> 1 | I13: =SUMIFS('Class Results'!J$10:J$362,'Class Results'!$A$10:$A$362,$A13, 'Class Results'!$C$10:$C$362,$B13) -> 0 | J13: =SUMIFS('Class Results'!K$10:K$362,'Class Results'!$A$10:$A$362,$A13, 'Class Results'!$C$10:$C$362,$B13) -> 0 | L13: =SUMIFS('Class Results'!L$10:L$362,'Class Results'!$A$10:$A$362,$A13, 'Class Results'!$C$10:$C$362,$B13) -> 0 | M13: =SUMIFS('Class Results'!M$10:M$362,'Class Results'!$A$10:$A$362,$A13, 'Class Results'!$C$10:$C$362,$B13) -> 1 | N13: =SUMIFS('Class Results'!N$10:N$362,'Class Results'!$A$10:$A$362,$A13, 'Class Results'!$C$10:$C$362,$B13) -> 1 | O13: =SUMIFS('Class Results'!O$10:O$362,'Class Results'!$A$10:$A$362,$A13, 'Class Results'!$C$10:$C$362,$B13) -> 1 | P13: =SUMIFS('Class Results'!P$10:P$362,'Class Results'!$A$10:$A$362,$A13, 'Class Results'!$C$10:$C$362,$B13) -> 0 | Q13: =SUMIFS('Class Results'!Q$10:Q$362,'Class Results'!$A$10:$A$362,$A13, 'Class Results'!$C$10:$C$362,$B13) -> 0 | R13: =SUMIFS('Class Results'!R$10:R$362,'Class Results'!$A$10:$A$362,$A13, 'Class Results'!$C$10:$C$362,$B13) -> 0 | S13: =SUMIFS('Class Results'!S$10:S$362,'Class Results'!$A$10:$A$362,$A13, 'Class Results'!$C$10:$C$362,$B13) -> 0 | ... V13: =SUMIFS('Class Results'!V$10:V$362,'Class Results'!$A$10:$A$362,$A13, 'Class Results'!$C$10:$C$362,$B13) -> 4 | W13: =IFERROR(AVERAGEIFS('Class Results'!W$10:W$362,'Class Results'!$A$10:$A$362,$A13, 'Class Results'!$C$10:$C$362,$B13),"") -> 8.75 | AD13: 2 | AE13: 1 | AF13: 2 | AG13: 3 | AH13: 3 | AI13: 2 | AJ13: 3 | AK13: 4 | AO13: =SUM(AD13:AN13) -> 20
A14: Grade 2 | B14: Female | C14: =SUMIFS('Class Results'!D$10:D$362,'Class Results'!$A$10:$A$362,$A14, 'Class Results'!$C$10:$C$362,$B14) -> 5 | D14: =SUMIFS('Class Results'!E$10:E$362,'Class Results'!$A$10:$A$362,$A14, 'Class Results'!$C$10:$C$362,$B14) -> 5 | E14: =SUMIFS('Class Results'!F$10:F$362,'Class Results'!$A$10:$A$362,$A14, 'Class Results'!$C$10:$C$362,$B14) -> 5 | F14: =SUMIFS('Class Results'!G$10:G$362,'Class Results'!$A$10:$A$362,$A14, 'Class Results'!$C$10:$C$362,$B14) -> 0 | G14: =SUMIFS('Class Results'!H$10:H$362,'Class Results'!$A$10:$A$362,$A14, 'Class Results'!$C$10:$C$362,$B14) -> 0 | H14: =SUMIFS('Class Results'!I$10:I$362,'Class Results'!$A$10:$A$362,$A14, 'Class Results'!$C$10:$C$362,$B14) -> 1 | I14: =SUMIFS('Class Results'!J$10:J$362,'Class Results'!$A$10:$A$362,$A14, 'Class Results'!$C$10:$C$362,$B14) -> 3 | J14: =SUMIFS('Class Results'!K$10:K$362,'Class Results'!$A$10:$A$362,$A14, 'Class Results'!$C$10:$C$362,$B14) -> 1 | L14: =SUMIFS('Class Results'!L$10:L$362,'Class Results'!$A$10:$A$362,$A14, 'Class Results'!$C$10:$C$362,$B14) -> 0 | M14: =SUMIFS('Class Results'!M$10:M$362,'Class Results'!$A$10:$A$362,$A14, 'Class Results'!$C$10:$C$362,$B14) -> 5 | N14: =SUMIFS('Class Results'!N$10:N$362,'Class Results'!$A$10:$A$362,$A14, 'Class Results'!$C$10:$C$362,$B14) -> 1 | O14: =SUMIFS('Class Results'!O$10:O$362,'Class Results'!$A$10:$A$362,$A14, 'Class Results'!$C$10:$C$362,$B14) -> 4 | P14: =SUMIFS('Class Results'!P$10:P$362,'Class Results'!$A$10:$A$362,$A14, 'Class Results'!$C$10:$C$362,$B14) -> 3 | Q14: =SUMIFS('Class Results'!Q$10:Q$362,'Class Results'!$A$10:$A$362,$A14, 'Class Results'!$C$10:$C$362,$B14) -> 1 | R14: =SUMIFS('Class Results'!R$10:R$362,'Class Results'!$A$10:$A$362,$A14, 'Class Results'!$C$10:$C$362,$B14) -> 4 | S14: =SUMIFS('Class Results'!S$10:S$362,'Class Results'!$A$10:$A$362,$A14, 'Class Results'!$C$10:$C$362,$B14) -> 3 | ... V14: =SUMIFS('Class Results'!V$10:V$362,'Class Results'!$A$10:$A$362,$A14, 'Class Results'!$C$10:$C$362,$B14) -> 5 | W14: =IFERROR(AVERAGEIFS('Class Results'!W$10:W$362,'Class Results'!$A$10:$A$362,$A14, 'Class Results'!$C$10:$C$362,$B14),"") -> 18.8
A15: Grade 3 | B15: =B11 -> Male | C15: =SUMIFS('Class Results'!D$10:D$362,'Class Results'!$A$10:$A$362,$A15, 'Class Results'!$C$10:$C$362,$B15) -> 4 | D15: =SUMIFS('Class Results'!E$10:E$362,'Class Results'!$A$10:$A$362,$A15, 'Class Results'!$C$10:$C$362,$B15) -> 4 | E15: =SUMIFS('Class Results'!F$10:F$362,'Class Results'!$A$10:$A$362,$A15, 'Class Results'!$C$10:$C$362,$B15) -> 4 | F15: =SUMIFS('Class Results'!G$10:G$362,'Class Results'!$A$10:$A$362,$A15, 'Class Results'!$C$10:$C$362,$B15) -> 0 | G15: =SUMIFS('Class Results'!H$10:H$362,'Class Results'!$A$10:$A$362,$A15, 'Class Results'!$C$10:$C$362,$B15) -> 3 | H15: =SUMIFS('Class Results'!I$10:I$362,'Class Results'!$A$10:$A$362,$A15, 'Class Results'!$C$10:$C$362,$B15) -> 1 | I15: =SUMIFS('Class Results'!J$10:J$362,'Class Results'!$A$10:$A$362,$A15, 'Class Results'!$C$10:$C$362,$B15) -> 0 | J15: =SUMIFS('Class Results'!K$10:K$362,'Class Results'!$A$10:$A$362,$A15, 'Class Results'!$C$10:$C$362,$B15) -> 0 | L15: =SUMIFS('Class Results'!L$10:L$362,'Class Results'!$A$10:$A$362,$A15, 'Class Results'!$C$10:$C$362,$B15) -> 3 | M15: =SUMIFS('Class Results'!M$10:M$362,'Class Results'!$A$10:$A$362,$A15, 'Class Results'!$C$10:$C$362,$B15) -> 4 | N15: =SUMIFS('Class Results'!N$10:N$362,'Class Results'!$A$10:$A$362,$A15, 'Class Results'!$C$10:$C$362,$B15) -> 4 | O15: =SUMIFS('Class Results'!O$10:O$362,'Class Results'!$A$10:$A$362,$A15, 'Class Results'!$C$10:$C$362,$B15) -> 1 | P15: =SUMIFS('Class Results'!P$10:P$362,'Class Results'!$A$10:$A$362,$A15, 'Class Results'!$C$10:$C$362,$B15) -> 0 | Q15: =SUMIFS('Class Results'!Q$10:Q$362,'Class Results'!$A$10:$A$362,$A15, 'Class Results'!$C$10:$C$362,$B15) -> 0 | R15: =SUMIFS('Class Results'!R$10:R$362,'Class Results'!$A$10:$A$362,$A15, 'Class Results'!$C$10:$C$362,$B15) -> 0 | S15: =SUMIFS('Class Results'!S$10:S$362,'Class Results'!$A$10:$A$362,$A15, 'Class Results'!$C$10:$C$362,$B15) -> 0 | T15: =IFERROR(AVERAGEIFS('Class Results'!T$10:T$362,'Class Results'!$A$10:$A$362,$A15, 'Class Results'!$C$10:$C$362,$B15),"") -> 0 | W15: =IFERROR(AVERAGEIFS('Class Results'!W$10:W$362,'Class Results'!$A$10:$A$362,$A15, 'Class Results'!$C$10:$C$362,$B15),"") -> 7.25
A16: Grade 3 | B16: Female | C16: =SUMIFS('Class Results'!D$10:D$362,'Class Results'!$A$10:$A$362,$A16, 'Class Results'!$C$10:$C$362,$B16) -> 4 | D16: =SUMIFS('Class Results'!E$10:E$362,'Class Results'!$A$10:$A$362,$A16, 'Class Results'!$C$10:$C$362,$B16) -> 4 | E16: =SUMIFS('Class Results'!F$10:F$362,'Class Results'!$A$10:$A$362,$A16, 'Class Results'!$C$10:$C$362,$B16) -> 4 | F16: =SUMIFS('Class Results'!G$10:G$362,'Class Results'!$A$10:$A$362,$A16, 'Class Results'!$C$10:$C$362,$B16) -> 0 | G16: =SUMIFS('Class Results'!H$10:H$362,'Class Results'!$A$10:$A$362,$A16, 'Class Results'!$C$10:$C$362,$B16) -> 2 | H16: =SUMIFS('Class Results'!I$10:I$362,'Class Results'!$A$10:$A$362,$A16, 'Class Results'!$C$10:$C$362,$B16) -> 2 | I16: =SUMIFS('Class Results'!J$10:J$362,'Class Results'!$A$10:$A$362,$A16, 'Class Results'!$C$10:$C$362,$B16) -> 0 | J16: =SUMIFS('Class Results'!K$10:K$362,'Class Results'!$A$10:$A$362,$A16, 'Class Results'!$C$10:$C$362,$B16) -> 0 | L16: =SUMIFS('Class Results'!L$10:L$362,'Class Results'!$A$10:$A$362,$A16, 'Class Results'!$C$10:$C$362,$B16) -> 2 | M16: =SUMIFS('Class Results'!M$10:M$362,'Class Results'!$A$10:$A$362,$A16, 'Class Results'!$C$10:$C$362,$B16) -> 4 | N16: =SUMIFS('Class Results'!N$10:N$362,'Class Results'!$A$10:$A$362,$A16, 'Class Results'!$C$10:$C$362,$B16) -> 3 | O16: =SUMIFS('Class Results'!O$10:O$362,'Class Results'!$A$10:$A$362,$A16, 'Class Results'!$C$10:$C$362,$B16) -> 2 | P16: =SUMIFS('Class Results'!P$10:P$362,'Class Results'!$A$10:$A$362,$A16, 'Class Results'!$C$10:$C$362,$B16) -> 1 | Q16: =SUMIFS('Class Results'!Q$10:Q$362,'Class Results'!$A$10:$A$362,$A16, 'Class Results'!$C$10:$C$362,$B16) -> 0 | R16: =SUMIFS('Class Results'!R$10:R$362,'Class Results'!$A$10:$A$362,$A16, 'Class Results'!$C$10:$C$362,$B16) -> 0 | S16: =SUMIFS('Class Results'!S$10:S$362,'Class Results'!$A$10:$A$362,$A16, 'Class Results'!$C$10:$C$362,$B16) -> 0 | T16: =IFERROR(AVERAGEIFS('Class Results'!T$10:T$362,'Class Results'!$A$10:$A$362,$A16, 'Class Results'!$C$10:$C$362,$B16),"") -> 0 | W16: =IFERROR(AVERAGEIFS('Class Results'!W$10:W$362,'Class Results'!$A$10:$A$362,$A16, 'Class Results'!$C$10:$C$362,$B16),"") -> 9.75
A18: TOTAL | C18: Language Matched ( LOI vs Learners) | D18: Number of Learners Assessed | E18: Total Enrolment | F18: Number of Learners Assessed | L18: Percentage of Learners Who Passed 75% Per Task by Grade Level | W18: Average Overall Score
F19: Emerging (Not Proficient) | G19: Emerging (Low Proficient) | H19: Developing (Nearly Proficient) | I19: Transitioning (Proficient) | J19: At Grade Level (Highly Proficient) | L19: Task A | M19: Task B | N19: Task C | O19: Task D | P19: Task E | Q19: Task F | R19: Task G | S19: Task H | T19: Task I | U19: Task J | V19: Task K
A20: Total Grade 1 | C20: =C11+C12 -> 6 | D20: =D11+D12 -> 7 | E20: =E11+E12 -> 7 | F20: =F11+F12 -> 0 | G20: =G11+G12 -> 3 | H20: =H11+H12 -> 3 | I20: =I11+I12 -> 1 | J20: =J11+J12 -> 0 | L20: =L11+L12 -> 0 | M20: =M11+M12 -> 3 | N20: =N11+N12 -> 3 | O20: =O11+O12 -> 0 | P20: =P11+P12 -> 1 | Q20: =Q11+Q12 -> 5 | R20: =R11+R12 -> 3 | S20: =S11+S12 -> 4 | ... V20: =V11+V12 -> 0 | W20: =IFERROR(AVERAGE(W11:W12),"") -> 20.29
A21: Total Grade 2 | C21: =C13+C14 -> 9 | D21: =D13+D14 -> 9 | E21: =E13+E14 -> 9 | F21: =F13+F14 -> 2 | G21: =G13+G14 -> 1 | H21: =H13+H14 -> 2 | I21: =I13+I14 -> 3 | J21: =J13+J14 -> 1 | L21: =L13+L14 -> 0 | M21: =M13+M14 -> 6 | N21: =N13+N14 -> 2 | O21: =O13+O14 -> 5 | P21: =P13+P14 -> 3 | Q21: =Q13+Q14 -> 1 | R21: =R13+R14 -> 4 | S21: =S13+S14 -> 3 | ... V21: =V13+V14 -> 9 | W21: =IFERROR(AVERAGE(W13:W14),"") -> 13.775
A22: Total Grade 3 | C22: =C15+C16 -> 8 | D22: =D15+D16 -> 8 | E22: =E15+E16 -> 8 | F22: =F15+F16 -> 0 | G22: =G15+G16 -> 5 | H22: =H15+H16 -> 3 | I22: =I15+I16 -> 0 | J22: =J15+J16 -> 0 | L22: =L15+L16 -> 5 | M22: =M15+M16 -> 8 | N22: =N15+N16 -> 7 | O22: =O15+O16 -> 3 | P22: =P15+P16 -> 1 | Q22: =Q15+Q16 -> 0 | R22: =R15+R16 -> 0 | S22: =S15+S16 -> 0 | T22: 0 | U22: =U15+U16 -> 0 | V22: =V15+V16 -> 0 | W22: =IFERROR(AVERAGE(W15:W16),"") -> 8.5
A23: Total Learners | C23: =SUM(C20:C22) -> 23 | D23: =SUM(D20:D22) -> 24 | E23: =SUM(E20:E22) -> 24 | F23: =SUM(F20:F22) -> 2 | G23: =SUM(G20:G22) -> 9 | H23: =SUM(H20:H22) -> 8 | I23: =SUM(I20:I22) -> 4 | J23: =SUM(J20:J22) -> 1 | L23: =L20+L21+L22 -> 5 | M23: =M20+M21+M22 -> 17 | N23: =N20+N21+N22 -> 12 | O23: =O20+O21+O22 -> 8 | P23: =P20+P21+P22 -> 5 | Q23: =Q20+Q21+Q22 -> 6 | R23: =R20+R21+R22 -> 7 | S23: =S20+S21+S22 -> 7 | ... V23: =V20+V21+V22 -> 9 | W23: =IFERROR(AVERAGE(W20:W22),"") -> 14.188333
F25: % of Learners Assessed | L25: % of Leaners who Passed 75% per Task by Grade Level
D26: Grade | E26: Sex | F26: Emerging (Not Proficient) | G26: Emerging (Low Proficient) | H26: Developing (Nearly Proficient) | I26: Transitioning (Proficient) | J26: At Grade Level (Highly Proficient) | L26: Task A | M26: Task B | N26: Task C | O26: Task D | P26: Task E | Q26: Task F | R26: Task G | S26: Task H | T26: Task I | U26: Task J | V26: Task K | W26: OverAll Score
D27: Grade 1 | E27: Male | F27: =IFERROR(F11/$D11,"") -> 0 | G27: =IFERROR(G11/$D11,"") -> 0 | H27: =IFERROR(H11/$D11,"") -> 0.66666667 | I27: =IFERROR(I11/$D11,"") -> 0.33333333 | J27: =IFERROR(J11/$D11,"") -> 0 | L27: =IFERROR(L11/$D11,"") -> 0 | M27: =IFERROR(M11/$D11,"") -> 0.33333333 | N27: =IFERROR(N11/$D11,"") -> 0.66666667 | O27: =IFERROR(O11/$D11,"") -> 0 | P27: =IFERROR(P11/$D11,"") -> 0.33333333 | Q27: =IFERROR(Q11/$D11,"") -> 1 | R27: =IFERROR(R11/$D11,"") -> 0.33333333 | S27: =IFERROR(S11/$D11,"") -> 0.66666667 | W27: =IFERROR(W11/$BD$7,"") -> 0.72371429
E28: Female | F28: =IFERROR(F12/$D12,"") -> 0 | G28: =IFERROR(G12/$D12,"") -> 0.75 | H28: =IFERROR(H12/$D12,"") -> 0.25 | I28: =IFERROR(I12/$D12,"") -> 0 | J28: =IFERROR(J12/$D12,"") -> 0 | L28: =IFERROR(L12/$D12,"") -> 0 | M28: =IFERROR(M12/$D12,"") -> 0.5 | N28: =IFERROR(N12/$D12,"") -> 0.25 | O28: =IFERROR(O12/$D12,"") -> 0 | P28: =IFERROR(P12/$D12,"") -> 0 | Q28: =IFERROR(Q12/$D12,"") -> 0.5 | R28: =IFERROR(R12/$D12,"") -> 0.5 | S28: =IFERROR(S12/$D12,"") -> 0.5 | T28: =IFERROR(T12/$D12,"") -> 0 | W28: =IFERROR(W12/$BD$7,"") -> 0.43571429
D29: Grade 2 | E29: Male | F29: =IFERROR(F13/$D13,"") -> 0.5 | G29: =IFERROR(G13/$D13,"") -> 0.25 | H29: =IFERROR(H13/$D13,"") -> 0.25 | I29: =IFERROR(I13/$D13,"") -> 0 | J29: =IFERROR(J13/$D13,"") -> 0 | L29: =IFERROR(L13/$D13,"") -> 0 | M29: =IFERROR(M13/$D13,"") -> 0.25 | N29: =IFERROR(N13/$D13,"") -> 0.25 | O29: =IFERROR(O13/$D13,"") -> 0.25 | P29: =IFERROR(P13/$D13,"") -> 0 | Q29: =IFERROR(Q13/$D13,"") -> 0 | R29: =IFERROR(R13/$D13,"") -> 0 | S29: =IFERROR(S13/$D13,"") -> 0 | ... V29: =IFERROR(V13/$D13,"") -> 1 | W29: =IFERROR(W13/$BD$8,"") -> 0.35
E30: Female | F30: =IFERROR(F14/$D14,"") -> 0 | G30: =IFERROR(G14/$D14,"") -> 0 | H30: =IFERROR(H14/$D14,"") -> 0.2 | I30: =IFERROR(I14/$D14,"") -> 0.6 | J30: =IFERROR(J14/$D14,"") -> 0.2 | L30: =IFERROR(L14/$D14,"") -> 0 | M30: =IFERROR(M14/$D14,"") -> 1 | N30: =IFERROR(N14/$D14,"") -> 0.2 | O30: =IFERROR(O14/$D14,"") -> 0.8 | P30: =IFERROR(P14/$D14,"") -> 0.6 | Q30: =IFERROR(Q14/$D14,"") -> 0.2 | R30: =IFERROR(R14/$D14,"") -> 0.8 | S30: =IFERROR(S14/$D14,"") -> 0.6 | ... V30: =IFERROR(V14/$D14,"") -> 1 | W30: =IFERROR(W14/$BD$8,"") -> 0.752
D31: Grade 3 | E31: Male | F31: =IFERROR(F15/$D15,"") -> 0 | G31: =IFERROR(G15/$D15,"") -> 0.75 | H31: =IFERROR(H15/$D15,"") -> 0.25 | I31: =IFERROR(I15/$D15,"") -> 0 | J31: =IFERROR(J15/$D15,"") -> 0 | L31: =IFERROR(L15/$D15,"") -> 0.75 | M31: =IFERROR(M15/$D15,"") -> 1 | N31: =IFERROR(N15/$D15,"") -> 1 | O31: =IFERROR(O15/$D15,"") -> 0.25 | P31: =IFERROR(P15/$D15,"") -> 0 | Q31: =IFERROR(Q15/$D15,"") -> 0 | R31: =IFERROR(R15/$D15,"") -> 0 | S31: =IFERROR(S15/$D15,"") -> 0 | T31: =IFERROR(T15/AL$13,"") | W31: =IFERROR(W15/$BD$9,"") -> 0.3625
E32: Female | F32: =IFERROR(F16/$D16,"") -> 0 | G32: =IFERROR(G16/$D16,"") -> 0.5 | H32: =IFERROR(H16/$D16,"") -> 0.5 | I32: =IFERROR(I16/$D16,"") -> 0 | J32: =IFERROR(J16/$D16,"") -> 0 | L32: =IFERROR(L16/$D16,"") -> 0.5 | M32: =IFERROR(M16/$D16,"") -> 1 | N32: =IFERROR(N16/$D16,"") -> 0.75 | O32: =IFERROR(O16/$D16,"") -> 0.5 | P32: =IFERROR(P16/$D16,"") -> 0.25 | Q32: =IFERROR(Q16/$D16,"") -> 0 | R32: =IFERROR(R16/$D16,"") -> 0 | S32: =IFERROR(S16/$D16,"") -> 0 | T32: =IFERROR(T16/AL$13,"") | W32: =IFERROR(W16/$BD$9,"") -> 0.4875
AH48: =IFERROR(#REF!/$H$14,"") | AI48: =IFERROR(#REF!/$H$14,"")
